2020-05-26 20:44:59,550 INFO: boring twitter [in /Users/eli/Documents/swe/Python/flask/flask-mega-tutorial/boring-twitter/app/__init__.py:37]
2020-05-26 20:45:15,360 ERROR: Exception on /edit_profile [POST] [in /Library/Frameworks/Python.framework/Versions/3.6/lib/python3.6/site-packages/flask/app.py:1891]
Traceback (most recent call last):
  File "/Library/Frameworks/Python.framework/Versions/3.6/lib/python3.6/site-packages/sqlalchemy/engine/base.py", line 1244, in _execute_context
    cursor, statement, parameters, context
  File "/Library/Frameworks/Python.framework/Versions/3.6/lib/python3.6/site-packages/sqlalchemy/engine/default.py", line 550, in do_execute
    cursor.execute(statement, parameters)
sqlite3.IntegrityError: UNIQUE constraint failed: user.username

The above exception was the direct cause of the following exception:

Traceback (most recent call last):
  File "/Library/Frameworks/Python.framework/Versions/3.6/lib/python3.6/site-packages/flask/app.py", line 2446, in wsgi_app
    response = self.full_dispatch_request()
  File "/Library/Frameworks/Python.framework/Versions/3.6/lib/python3.6/site-packages/flask/app.py", line 1951, in full_dispatch_request
    rv = self.handle_user_exception(e)
  File "/Library/Frameworks/Python.framework/Versions/3.6/lib/python3.6/site-packages/flask/app.py", line 1820, in handle_user_exception
    reraise(exc_type, exc_value, tb)
  File "/Library/Frameworks/Python.framework/Versions/3.6/lib/python3.6/site-packages/flask/_compat.py", line 39, in reraise
    raise value
  File "/Library/Frameworks/Python.framework/Versions/3.6/lib/python3.6/site-packages/flask/app.py", line 1949, in full_dispatch_request
    rv = self.dispatch_request()
  File "/Library/Frameworks/Python.framework/Versions/3.6/lib/python3.6/site-packages/flask/app.py", line 1935, in dispatch_request
    return self.view_functions[rule.endpoint](**req.view_args)
  File "/Library/Frameworks/Python.framework/Versions/3.6/lib/python3.6/site-packages/flask_login/utils.py", line 272, in decorated_view
    return func(*args, **kwargs)
  File "/Users/eli/Documents/swe/Python/flask/flask-mega-tutorial/boring-twitter/app/routes.py", line 96, in edit_profile
    db.session.commit()
  File "/Library/Frameworks/Python.framework/Versions/3.6/lib/python3.6/site-packages/sqlalchemy/orm/scoping.py", line 162, in do
    return getattr(self.registry(), name)(*args, **kwargs)
  File "/Library/Frameworks/Python.framework/Versions/3.6/lib/python3.6/site-packages/sqlalchemy/orm/session.py", line 1027, in commit
    self.transaction.commit()
  File "/Library/Frameworks/Python.framework/Versions/3.6/lib/python3.6/site-packages/sqlalchemy/orm/session.py", line 494, in commit
    self._prepare_impl()
  File "/Library/Frameworks/Python.framework/Versions/3.6/lib/python3.6/site-packages/sqlalchemy/orm/session.py", line 473, in _prepare_impl
    self.session.flush()
  File "/Library/Frameworks/Python.framework/Versions/3.6/lib/python3.6/site-packages/sqlalchemy/orm/session.py", line 2459, in flush
    self._flush(objects)
  File "/Library/Frameworks/Python.framework/Versions/3.6/lib/python3.6/site-packages/sqlalchemy/orm/session.py", line 2597, in _flush
    transaction.rollback(_capture_exception=True)
  File "/Library/Frameworks/Python.framework/Versions/3.6/lib/python3.6/site-packages/sqlalchemy/util/langhelpers.py", line 68, in __exit__
    compat.reraise(exc_type, exc_value, exc_tb)
  File "/Library/Frameworks/Python.framework/Versions/3.6/lib/python3.6/site-packages/sqlalchemy/util/compat.py", line 154, in reraise
    raise value
  File "/Library/Frameworks/Python.framework/Versions/3.6/lib/python3.6/site-packages/sqlalchemy/orm/session.py", line 2557, in _flush
    flush_context.execute()
  File "/Library/Frameworks/Python.framework/Versions/3.6/lib/python3.6/site-packages/sqlalchemy/orm/unitofwork.py", line 422, in execute
    rec.execute(self)
  File "/Library/Frameworks/Python.framework/Versions/3.6/lib/python3.6/site-packages/sqlalchemy/orm/unitofwork.py", line 589, in execute
    uow,
  File "/Library/Frameworks/Python.framework/Versions/3.6/lib/python3.6/site-packages/sqlalchemy/orm/persistence.py", line 236, in save_obj
    update,
  File "/Library/Frameworks/Python.framework/Versions/3.6/lib/python3.6/site-packages/sqlalchemy/orm/persistence.py", line 996, in _emit_update_statements
    statement, multiparams
  File "/Library/Frameworks/Python.framework/Versions/3.6/lib/python3.6/site-packages/sqlalchemy/engine/base.py", line 988, in execute
    return meth(self, multiparams, params)
  File "/Library/Frameworks/Python.framework/Versions/3.6/lib/python3.6/site-packages/sqlalchemy/sql/elements.py", line 287, in _execute_on_connection
    return connection._execute_clauseelement(self, multiparams, params)
  File "/Library/Frameworks/Python.framework/Versions/3.6/lib/python3.6/site-packages/sqlalchemy/engine/base.py", line 1107, in _execute_clauseelement
    distilled_params,
  File "/Library/Frameworks/Python.framework/Versions/3.6/lib/python3.6/site-packages/sqlalchemy/engine/base.py", line 1248, in _execute_context
    e, statement, parameters, cursor, context
  File "/Library/Frameworks/Python.framework/Versions/3.6/lib/python3.6/site-packages/sqlalchemy/engine/base.py", line 1466, in _handle_dbapi_exception
    util.raise_from_cause(sqlalchemy_exception, exc_info)
  File "/Library/Frameworks/Python.framework/Versions/3.6/lib/python3.6/site-packages/sqlalchemy/util/compat.py", line 399, in raise_from_cause
    reraise(type(exception), exception, tb=exc_tb, cause=cause)
  File "/Library/Frameworks/Python.framework/Versions/3.6/lib/python3.6/site-packages/sqlalchemy/util/compat.py", line 153, in reraise
    raise value.with_traceback(tb)
  File "/Library/Frameworks/Python.framework/Versions/3.6/lib/python3.6/site-packages/sqlalchemy/engine/base.py", line 1244, in _execute_context
    cursor, statement, parameters, context
  File "/Library/Frameworks/Python.framework/Versions/3.6/lib/python3.6/site-packages/sqlalchemy/engine/default.py", line 550, in do_execute
    cursor.execute(statement, parameters)
sqlalchemy.exc.IntegrityError: (sqlite3.IntegrityError) UNIQUE constraint failed: user.username
[SQL: UPDATE user SET username=?, about_me=? WHERE user.id = ?]
[parameters: ('eli', 'clouds + darkness', 1)]
(Background on this error at: http://sqlalche.me/e/gkpj)
2020-05-29 19:46:26,590 INFO: boring twitter [in /Users/eli/Documents/swe/Python/flask/flask-mega-tutorial/boring-twitter/app/__init__.py:37]
2020-05-29 19:46:50,067 INFO: boring twitter [in /Users/eli/Documents/swe/Python/flask/flask-mega-tutorial/boring-twitter/app/__init__.py:37]
2020-05-30 20:36:54,090 INFO: boring twitter [in /Users/eli/Documents/swe/Python/flask/flask-mega-tutorial/boring-twitter/app/__init__.py:37]
2020-05-30 22:56:20,779 INFO: boring twitter [in /Users/eli/Documents/swe/Python/flask/flask-mega-tutorial/boring-twitter/app/__init__.py:37]
2020-05-30 23:13:23,768 INFO: boring twitter [in /Users/eli/Documents/swe/Python/flask/flask-mega-tutorial/boring-twitter/app/__init__.py:37]
2020-05-30 23:15:55,712 INFO: boring twitter [in /Users/eli/Documents/swe/Python/flask/flask-mega-tutorial/boring-twitter/app/__init__.py:37]
2020-05-30 23:17:30,021 INFO: boring twitter [in /Users/eli/Documents/swe/Python/flask/flask-mega-tutorial/boring-twitter/app/__init__.py:37]
2020-05-30 23:18:30,878 INFO: boring twitter [in /Users/eli/Documents/swe/Python/flask/flask-mega-tutorial/boring-twitter/app/__init__.py:37]
2020-05-30 23:20:15,866 INFO: boring twitter [in /Users/eli/Documents/swe/Python/flask/flask-mega-tutorial/boring-twitter/app/__init__.py:37]
2020-05-30 23:23:51,089 INFO: boring twitter [in /Users/eli/Documents/swe/Python/flask/flask-mega-tutorial/boring-twitter/app/__init__.py:37]
2020-05-30 23:59:02,586 INFO: boring twitter [in /Users/eli/Documents/swe/Python/flask/flask-mega-tutorial/boring-twitter/app/__init__.py:37]
2020-05-30 23:59:32,752 INFO: boring twitter [in /Users/eli/Documents/swe/Python/flask/flask-mega-tutorial/boring-twitter/app/__init__.py:37]
2020-05-31 00:00:00,829 ERROR: Exception on /follow/problem [POST] [in /Library/Frameworks/Python.framework/Versions/3.8/lib/python3.8/site-packages/flask/app.py:1891]
Traceback (most recent call last):
  File "/Library/Frameworks/Python.framework/Versions/3.8/lib/python3.8/site-packages/flask/app.py", line 2447, in wsgi_app
    response = self.full_dispatch_request()
  File "/Library/Frameworks/Python.framework/Versions/3.8/lib/python3.8/site-packages/flask/app.py", line 1953, in full_dispatch_request
    return self.finalize_request(rv)
  File "/Library/Frameworks/Python.framework/Versions/3.8/lib/python3.8/site-packages/flask/app.py", line 1968, in finalize_request
    response = self.make_response(rv)
  File "/Library/Frameworks/Python.framework/Versions/3.8/lib/python3.8/site-packages/flask/app.py", line 2097, in make_response
    raise TypeError(
TypeError: The view function did not return a valid response. The function either returned None or ended without a return statement.
